<?xml version="1.0" encoding="utf-8"?>
<!-- This URDF was automatically created by SolidWorks to URDF Exporter! Originally created by Stephen Brawner (brawner@gmail.com) 
     Commit Version: 1.6.0-4-g7f85cfe  Build Version: 1.6.7995.38578
     For more information, please see http://wiki.ros.org/sw_urdf_exporter -->
<robot
  name="shimizu_gantry_system">
  <link
    name="gantry_x">
    <inertial>
      <origin
        xyz="11.601 -15.827 4.9939"
        rpy="0 0 0" />
      <mass
        value="11710" />
      <inertia
        ixx="63802"
        ixy="1.1691E-11"
        ixz="2.0818E-13"
        iyy="45367"
        iyz="0.050437"
        izz="107050" />
    </inertial>
    <visual>
      <origin
        xyz="0 0 0"
        rpy="0 0 0" />
      <geometry>
        <mesh
          filename="package://shimizu_gantry_system/meshes/gantry_x.STL" />
      </geometry>
      <material
        name="">
        <color
          rgba="0.79216 0.81961 0.93333 1" />
      </material>
    </visual>
    <collision>
      <origin
        xyz="0 0 0"
        rpy="0 0 0" />
      <geometry>
        <mesh
          filename="package://shimizu_gantry_system/meshes/gantry_x.STL" />
      </geometry>
    </collision>
  </link>
  <link
    name="gantry_y">
    <inertial>
      <origin
        xyz="-0.184 0.17153 3.0187"
        rpy="0 0 0" />
      <mass
        value="740.03" />
      <inertia
        ixx="2278.6"
        ixy="1.7659E-08"
        ixz="2.8771E-11"
        iyy="2279.9"
        iyz="0.002039"
        izz="17.062" />
    </inertial>
    <visual>
      <origin
        xyz="0 0 0"
        rpy="0 0 0" />
      <geometry>
        <mesh
          filename="package://shimizu_gantry_system/meshes/gantry_y.STL" />
      </geometry>
      <material
        name="">
        <color
          rgba="0.79216 0.81961 0.93333 1" />
      </material>
    </visual>
    <collision>
      <origin
        xyz="0 0 0"
        rpy="0 0 0" />
      <geometry>
        <mesh
          filename="package://shimizu_gantry_system/meshes/gantry_y.STL" />
      </geometry>
    </collision>
  </link>
  <joint
    name="x_to_y"
    type="prismatic">
    <origin
      xyz="8.5487 -16.257 7.5966"
      rpy="1.5708 0 1.5708" />
    <parent
      link="gantry_x" />
    <child
      link="gantry_y" />
    <axis
      xyz="1 0 0" />
    <limit
      lower="0"
      upper="0"
      effort="0"
      velocity="0" />
  </joint>
  <link
    name="base">
    <inertial>
      <origin
        xyz="0.36884 7.2709 17.038"
        rpy="0 0 0" />
      <mass
        value="645.33" />
      <inertia
        ixx="213.99"
        ixy="0.12239"
        ixz="-0.00078064"
        iyy="42.439"
        iyz="-0.00056304"
        izz="227.81" />
    </inertial>
    <visual>
      <origin
        xyz="0 0 0"
        rpy="0 0 0" />
      <geometry>
        <mesh
          filename="package://shimizu_gantry_system/meshes/base.STL" />
      </geometry>
      <material
        name="">
        <color
          rgba="0.79216 0.81961 0.93333 1" />
      </material>
    </visual>
    <collision>
      <origin
        xyz="0 0 0"
        rpy="0 0 0" />
      <geometry>
        <mesh
          filename="package://shimizu_gantry_system/meshes/base.STL" />
      </geometry>
    </collision>
  </link>
  <joint
    name="y_to_base"
    type="prismatic">
    <origin
      xyz="16.87 -7.5966 2.4892"
      rpy="0 -1.5708 0" />
    <parent
      link="gantry_y" />
    <child
      link="base" />
    <axis
      xyz="1 0 0" />
    <limit
      lower="0"
      upper="0"
      effort="0"
      velocity="0" />
  </joint>
  <link
    name="link1">
    <inertial>
      <origin
        xyz="0.15386 -0.010839 -0.23834"
        rpy="0 0 0" />
      <mass
        value="39.488" />
      <inertia
        ixx="0.82415"
        ixy="-0.13884"
        ixz="-0.16266"
        iyy="1.5307"
        iyz="0.086029"
        izz="1.6236" />
    </inertial>
    <visual>
      <origin
        xyz="0 0 0"
        rpy="0 0 0" />
      <geometry>
        <mesh
          filename="package://shimizu_gantry_system/meshes/link1.STL" />
      </geometry>
      <material
        name="">
        <color
          rgba="0.75294 0.75294 0.75294 1" />
      </material>
    </visual>
    <collision>
      <origin
        xyz="0 0 0"
        rpy="0 0 0" />
      <geometry>
        <mesh
          filename="package://shimizu_gantry_system/meshes/link1.STL" />
      </geometry>
    </collision>
  </link>
  <joint
    name="joint1"
    type="continuous">
    <origin
      xyz="0.44563 5.7729 17.038"
      rpy="1.5708 0 0" />
    <parent
      link="base" />
    <child
      link="link1" />
    <axis
      xyz="0 0 1" />
  </joint>
  <link
    name="link2">
    <inertial>
      <origin
        xyz="0.020078 0.13105 0.39436"
        rpy="0 0 0" />
      <mass
        value="26.224" />
      <inertia
        ixx="2.763"
        ixy="-0.0029337"
        ixz="-0.019264"
        iyy="2.8501"
        iyz="-0.03169"
        izz="0.15604" />
    </inertial>
    <visual>
      <origin
        xyz="0 0 0"
        rpy="0 0 0" />
      <geometry>
        <mesh
          filename="package://shimizu_gantry_system/meshes/link2.STL" />
      </geometry>
      <material
        name="">
        <color
          rgba="0.75294 0.75294 0.75294 1" />
      </material>
    </visual>
    <collision>
      <origin
        xyz="0 0 0"
        rpy="0 0 0" />
      <geometry>
        <mesh
          filename="package://shimizu_gantry_system/meshes/link2.STL" />
      </geometry>
    </collision>
  </link>
  <joint
    name="joint2"
    type="continuous">
    <origin
      xyz="0.32 0.078 -0.1973"
      rpy="0 1.5708 0" />
    <parent
      link="link1" />
    <child
      link="link2" />
    <axis
      xyz="0 1 0" />
  </joint>
  <link
    name="link3">
    <inertial>
      <origin
        xyz="0.1709 -0.072562 0.13441"
        rpy="0 0 0" />
      <mass
        value="41.069" />
      <inertia
        ixx="0.94589"
        ixy="-0.0096923"
        ixz="-0.49972"
        iyy="2.6922"
        iyz="-0.024444"
        izz="2.2908" />
    </inertial>
    <visual>
      <origin
        xyz="0 0 0"
        rpy="0 0 0" />
      <geometry>
        <mesh
          filename="package://shimizu_gantry_system/meshes/link3.STL" />
      </geometry>
      <material
        name="">
        <color
          rgba="0.75294 0.75294 0.75294 1" />
      </material>
    </visual>
    <collision>
      <origin
        xyz="0 0 0"
        rpy="0 0 0" />
      <geometry>
        <mesh
          filename="package://shimizu_gantry_system/meshes/link3.STL" />
      </geometry>
    </collision>
  </link>
  <joint
    name="joint3"
    type="continuous">
    <origin
      xyz="0 0 0.87"
      rpy="0 0 0" />
    <parent
      link="link2" />
    <child
      link="link3" />
    <axis
      xyz="0 1 0" />
  </joint>
  <link
    name="link4">
    <inertial>
      <origin
        xyz="0.10063 -0.0026884 -7.1301E-06"
        rpy="0 0 0" />
      <mass
        value="2.0071" />
      <inertia
        ixx="0.0038933"
        ixy="0.00064975"
        ixz="8.2647E-07"
        iyy="0.013325"
        iyz="-4.7432E-07"
        izz="0.013382" />
    </inertial>
    <visual>
      <origin
        xyz="0 0 0"
        rpy="0 0 0" />
      <geometry>
        <mesh
          filename="package://shimizu_gantry_system/meshes/link4.STL" />
      </geometry>
      <material
        name="">
        <color
          rgba="0.75294 0.75294 0.75294 1" />
      </material>
    </visual>
    <collision>
      <origin
        xyz="0 0 0"
        rpy="0 0 0" />
      <geometry>
        <mesh
          filename="package://shimizu_gantry_system/meshes/link4.STL" />
      </geometry>
    </collision>
  </link>
  <joint
    name="joint4"
    type="continuous">
    <origin
      xyz="0.83 -0.0665 0.225"
      rpy="0 0 0" />
    <parent
      link="link3" />
    <child
      link="link4" />
    <axis
      xyz="1 0 0" />
  </joint>
  <link
    name="link5">
    <inertial>
      <origin
        xyz="0.050878 -0.022728 -5.4373E-11"
        rpy="0 0 0" />
      <mass
        value="3.6409" />
      <inertia
        ixx="0.0192"
        ixy="-0.0045288"
        ixz="-3.9525E-12"
        iyy="0.019576"
        iyz="-2.9081E-13"
        izz="0.028883" />
    </inertial>
    <visual>
      <origin
        xyz="0 0 0"
        rpy="0 0 0" />
      <geometry>
        <mesh
          filename="package://shimizu_gantry_system/meshes/link5.STL" />
      </geometry>
      <material
        name="">
        <color
          rgba="0.75294 0.75294 0.75294 1" />
      </material>
    </visual>
    <collision>
      <origin
        xyz="0 0 0"
        rpy="0 0 0" />
      <geometry>
        <mesh
          filename="package://shimizu_gantry_system/meshes/link5.STL" />
      </geometry>
    </collision>
  </link>
  <joint
    name="joint5"
    type="continuous">
    <origin
      xyz="0.1995 0 0"
      rpy="0 0 0" />
    <parent
      link="link4" />
    <child
      link="link5" />
    <axis
      xyz="0 1 0" />
  </joint>
  <link
    name="link6">
    <inertial>
      <origin
        xyz="0 2.2024E-05 -0.010468"
        rpy="0 0 0" />
      <mass
        value="0.22702" />
      <inertia
        ixx="0.00022782"
        ixy="-4.7234E-22"
        ixz="6.1755E-21"
        iyy="0.00022856"
        iyz="-3.9842E-08"
        izz="0.00043885" />
    </inertial>
    <visual>
      <origin
        xyz="0 0 0"
        rpy="0 0 0" />
      <geometry>
        <mesh
          filename="package://shimizu_gantry_system/meshes/link6.STL" />
      </geometry>
      <material
        name="">
        <color
          rgba="0.75294 0.75294 0.75294 1" />
      </material>
    </visual>
    <collision>
      <origin
        xyz="0 0 0"
        rpy="0 0 0" />
      <geometry>
        <mesh
          filename="package://shimizu_gantry_system/meshes/link6.STL" />
      </geometry>
    </collision>
  </link>
  <joint
    name="joint6"
    type="continuous">
    <origin
      xyz="0.1665 -0.009 0"
      rpy="1.5708 0 -1.5708" />
    <parent
      link="link5" />
    <child
      link="link6" />
    <axis
      xyz="0 0 1" />
  </joint>
</robot>