<?xml version="1.0" encoding="utf-8"?>
<!-- This URDF was automatically created by SolidWorks to URDF Exporter! Originally created by Stephen Brawner (brawner@gmail.com) 
     Commit Version: 1.6.0-4-g7f85cfe  Build Version: 1.6.7995.38578
     For more information, please see http://wiki.ros.org/sw_urdf_exporter -->
<robot
  name="shimizu_gantry_system">
  <link
    name="structure">
    <inertial>
      <origin
        xyz="4.0286 4.6859 1.1281"
        rpy="0 0 0" />
      <mass
        value="12293" />
      <inertia
        ixx="64316"
        ixy="4.7295E-12"
        ixz="2.1029E-13"
        iyy="45881"
        iyz="-0.0025005"
        izz="107060" />
    </inertial>
    <visual>
      <origin
        xyz="0 0 0"
        rpy="0 0 0" />
      <geometry>
        <mesh
          filename="package://shimizu_gantry_system/meshes/structure.STL" />
      </geometry>
      <material
        name="">
        <color
          rgba="0.79216 0.81961 0.93333 1" />
      </material>
    </visual>
    <collision>
      <origin
        xyz="0 0 0"
        rpy="0 0 0" />
      <geometry>
        <mesh
          filename="package://shimizu_gantry_system/meshes/structure.STL" />
      </geometry>
    </collision>
  </link>
  <link
    name="x_rail">
    <inertial>
      <origin
        xyz="3.0187 0.184 0.17153"
        rpy="0 0 0" />
      <mass
        value="740.03" />
      <inertia
        ixx="17.062"
        ixy="-9.0349E-15"
        ixz="0.002039"
        iyy="2278.6"
        iyz="4.5596E-16"
        izz="2279.9" />
    </inertial>
    <visual>
      <origin
        xyz="0 0 0"
        rpy="0 0 0" />
      <geometry>
        <mesh
          filename="package://shimizu_gantry_system/meshes/x_rail.STL" />
      </geometry>
      <material
        name="">
        <color
          rgba="0.79216 0.81961 0.93333 1" />
      </material>
    </visual>
    <collision>
      <origin
        xyz="0 0 0"
        rpy="0 0 0" />
      <geometry>
        <mesh
          filename="package://shimizu_gantry_system/meshes/x_rail.STL" />
      </geometry>
    </collision>
  </link>
  <joint
    name="joint_structure_rail"
    type="prismatic">
    <origin
      xyz="1.0082 3.756 3.7013"
      rpy="0 0 0" />
    <parent
      link="structure" />
    <child
      link="x_rail" />
    <axis
      xyz="0 1 0" />
    <limit
      lower="0"
      upper="0"
      effort="0"
      velocity="0" />
  </joint>
  <link
    name="carriage">
    <inertial>
      <origin
        xyz="-0.076789 3.2516E-06 -0.81076"
        rpy="0 0 0" />
      <mass
        value="645.33" />
      <inertia
        ixx="213.99"
        ixy="-0.00078064"
        ixz="-0.12239"
        iyy="227.81"
        iyz="0.00056304"
        izz="42.439" />
    </inertial>
    <visual>
      <origin
        xyz="0 0 0"
        rpy="0 0 0" />
      <geometry>
        <mesh
          filename="package://shimizu_gantry_system/meshes/carriage.STL" />
      </geometry>
      <material
        name="">
        <color
          rgba="0.79216 0.81961 0.93333 1" />
      </material>
    </visual>
    <collision>
      <origin
        xyz="0 0 0"
        rpy="0 0 0" />
      <geometry>
        <mesh
          filename="package://shimizu_gantry_system/meshes/carriage.STL" />
      </geometry>
    </collision>
  </link>
  <joint
    name="joint_rail_carriage"
    type="prismatic">
    <origin
      xyz="2.0675 0.184 -1.1204"
      rpy="3.1416 0 0" />
    <parent
      link="x_rail" />
    <child
      link="carriage" />
    <axis
      xyz="-1 0 0" />
    <limit
      lower="0"
      upper="0"
      effort="0"
      velocity="0" />
  </joint>
  <link
    name="link_1">
    <inertial>
      <origin
        xyz="0.15386 -0.010839 0.14546"
        rpy="0 0 0" />
      <mass
        value="39.488" />
      <inertia
        ixx="0.82415"
        ixy="-0.13884"
        ixz="-0.16266"
        iyy="1.5307"
        iyz="0.086029"
        izz="1.6236" />
    </inertial>
    <visual>
      <origin
        xyz="0 0 0"
        rpy="0 0 0" />
      <geometry>
        <mesh
          filename="package://shimizu_gantry_system/meshes/link_1.STL" />
      </geometry>
      <material
        name="">
        <color
          rgba="0.75294 0.75294 0.75294 1" />
      </material>
    </visual>
    <collision>
      <origin
        xyz="0 0 0"
        rpy="0 0 0" />
      <geometry>
        <mesh
          filename="package://shimizu_gantry_system/meshes/link_1.STL" />
      </geometry>
    </collision>
  </link>
  <joint
    name="joint_1"
    type="continuous">
    <origin
      xyz="0 0 0.2635"
      rpy="0 0 0.0062665" />
    <parent
      link="carriage" />
    <child
      link="link_1" />
    <axis
      xyz="0 0 1" />
  </joint>
  <link
    name="link_2">
    <inertial>
      <origin
        xyz="0.020078 0.056046 0.39436"
        rpy="0 0 0" />
      <mass
        value="26.224" />
      <inertia
        ixx="2.763"
        ixy="-0.0029337"
        ixz="-0.019264"
        iyy="2.8501"
        iyz="-0.03169"
        izz="0.15604" />
    </inertial>
    <visual>
      <origin
        xyz="0 0 0"
        rpy="0 0 0" />
      <geometry>
        <mesh
          filename="package://shimizu_gantry_system/meshes/link_2.STL" />
      </geometry>
      <material
        name="">
        <color
          rgba="0.75294 0.75294 0.75294 1" />
      </material>
    </visual>
    <collision>
      <origin
        xyz="0 0 0"
        rpy="0 0 0" />
      <geometry>
        <mesh
          filename="package://shimizu_gantry_system/meshes/link_2.STL" />
      </geometry>
    </collision>
  </link>
  <joint
    name="joint_2"
    type="continuous">
    <origin
      xyz="0.32 0.08996 0.1865"
      rpy="0 0 0" />
    <parent
      link="link_1" />
    <child
      link="link_2" />
    <axis
      xyz="0 1 0" />
  </joint>
  <link
    name="link_3">
    <inertial>
      <origin
        xyz="0.1709 -0.091062 0.13441"
        rpy="0 0 0" />
      <mass
        value="41.069" />
      <inertia
        ixx="0.9459"
        ixy="-0.0096924"
        ixz="-0.49972"
        iyy="2.6922"
        iyz="-0.024444"
        izz="2.2908" />
    </inertial>
    <visual>
      <origin
        xyz="0 0 0"
        rpy="0 0 0" />
      <geometry>
        <mesh
          filename="package://shimizu_gantry_system/meshes/link_3.STL" />
      </geometry>
      <material
        name="">
        <color
          rgba="0.75294 0.75294 0.75294 1" />
      </material>
    </visual>
    <collision>
      <origin
        xyz="0 0 0"
        rpy="0 0 0" />
      <geometry>
        <mesh
          filename="package://shimizu_gantry_system/meshes/link_3.STL" />
      </geometry>
    </collision>
  </link>
  <joint
    name="joint_3"
    type="continuous">
    <origin
      xyz="0 -0.00496 0.87"
      rpy="0 0 0" />
    <parent
      link="link_2" />
    <child
      link="link_3" />
    <axis
      xyz="0 1 0" />
  </joint>
  <link
    name="link_4">
    <inertial>
      <origin
        xyz="0.095631 -0.0026884 -7.1299E-06"
        rpy="0 0 0" />
      <mass
        value="2.0071" />
      <inertia
        ixx="0.0038933"
        ixy="0.00064975"
        ixz="8.2641E-07"
        iyy="0.013325"
        iyz="-4.7428E-07"
        izz="0.013382" />
    </inertial>
    <visual>
      <origin
        xyz="0 0 0"
        rpy="0 0 0" />
      <geometry>
        <mesh
          filename="package://shimizu_gantry_system/meshes/link_4.STL" />
      </geometry>
      <material
        name="">
        <color
          rgba="0.75294 0.75294 0.75294 1" />
      </material>
    </visual>
    <collision>
      <origin
        xyz="0 0 0"
        rpy="0 0 0" />
      <geometry>
        <mesh
          filename="package://shimizu_gantry_system/meshes/link_4.STL" />
      </geometry>
    </collision>
  </link>
  <joint
    name="joint_4"
    type="continuous">
    <origin
      xyz="0.82052 -0.085 0.225"
      rpy="0 0 0" />
    <parent
      link="link_3" />
    <child
      link="link_4" />
    <axis
      xyz="1 0 0" />
  </joint>
  <link
    name="link_5">
    <inertial>
      <origin
        xyz="0.050878 0.028472 -5.4122E-11"
        rpy="0 0 0" />
      <mass
        value="3.6409" />
      <inertia
        ixx="0.0192"
        ixy="-0.0045288"
        ixz="-3.9585E-12"
        iyy="0.019576"
        iyz="-1.4292E-13"
        izz="0.028883" />
    </inertial>
    <visual>
      <origin
        xyz="0 0 0"
        rpy="0 0 0" />
      <geometry>
        <mesh
          filename="package://shimizu_gantry_system/meshes/link_5.STL" />
      </geometry>
      <material
        name="">
        <color
          rgba="0.75294 0.75294 0.75294 1" />
      </material>
    </visual>
    <collision>
      <origin
        xyz="0 0 0"
        rpy="0 0 0" />
      <geometry>
        <mesh
          filename="package://shimizu_gantry_system/meshes/link_5.STL" />
      </geometry>
    </collision>
  </link>
  <joint
    name="joint_5"
    type="continuous">
    <origin
      xyz="0.1945 -0.04579 0"
      rpy="0 0 0" />
    <parent
      link="link_4" />
    <child
      link="link_5" />
    <axis
      xyz="0 1 0" />
  </joint>
  <link
    name="link_6">
    <inertial>
      <origin
        xyz="-0.011532 2.2024E-05 0"
        rpy="0 0 0" />
      <mass
        value="0.22702" />
      <inertia
        ixx="0.00043885"
        ixy="3.9842E-08"
        ixz="-3.0309E-21"
        iyy="0.00022856"
        iyz="-1.0535E-20"
        izz="0.00022782" />
    </inertial>
    <visual>
      <origin
        xyz="0 0 0"
        rpy="0 0 0" />
      <geometry>
        <mesh
          filename="package://shimizu_gantry_system/meshes/link_6.STL" />
      </geometry>
      <material
        name="">
        <color
          rgba="0.75294 0.75294 0.75294 1" />
      </material>
    </visual>
    <collision>
      <origin
        xyz="0 0 0"
        rpy="0 0 0" />
      <geometry>
        <mesh
          filename="package://shimizu_gantry_system/meshes/link_6.STL" />
      </geometry>
    </collision>
  </link>
  <joint
    name="joint_6"
    type="continuous">
    <origin
      xyz="0.175 0.0422 0"
      rpy="0 0 0" />
    <parent
      link="link_5" />
    <child
      link="link_6" />
    <axis
      xyz="1 0 0" />
  </joint>
</robot>